Workbook
Name ___APC1: [1]Report!$F$13
Name ___ARR1: [1]Report!$G$8
Name ___INDEX_SHEET___: #REF!
Name ___INDEX_SHEET___: #REF!
Name ___INDEX_SHEET___: #REF!
Name ___INDEX_SHEET___: #REF!
Name ___INDEX_SHEET___: #REF!
Name ___INDEX_SHEET___: #REF!
Name ___INDEX_SHEET___: #REF!
Name ___INDEX_SHEET___: #REF!
Name ___INDEX_SHEET___: #REF!
Name ___INDEX_SHEET___: #REF!
Name __APC1: [1]Report!$F$13
Name __ARR1: [1]Report!$G$8
Name __Mth1: #REF!
Name __Mth1: #REF!
Name __Mth1: #REF!
Name __Mth1: #REF!
Name __Mth1: #REF!
Name __Mth1: #REF!
Name __Mth1: #REF!
Name __Mth1: #REF!
Name __Mth1: #REF!
Name __Mth1: #REF!
Name __Mth2: #REF!
Name __Mth2: #REF!
Name __Mth2: #REF!
Name __Mth2: #REF!
Name __Mth2: #REF!
Name __Mth2: #REF!
Name __Mth2: #REF!
Name __Mth4: #REF!
Name __Mth4: #REF!
Name __Mth4: #REF!
Name __Mth4: #REF!
Name __Mth4: #REF!
Name __Mth4: #REF!
Name __Mth4: #REF!
Name _APC1: [2]Report!$F$13
Name _ARR1: [2]Report!$G$8
Name _Mth5: #REF!
Name _Mth5: #REF!
Name _Mth5: #REF!
Name _Mth5: #REF!
Name _Mth5: #REF!
Name _Mth5: #REF!
Name _Mth5: #REF!
Name _Mth5: #REF!
Name _Mth5: #REF!
Name _Mth5: #REF!
Name _Mth6: #REF!
Name _Mth6: #REF!
Name _Mth6: #REF!
Name _Mth6: #REF!
Name _Mth6: #REF!
Name _Mth6: #REF!
Name _Mth6: #REF!
Name ABSENTISM: [3]MANPOWER!#REF!
Name ABSENTISM: [3]MANPOWER!#REF!
Name ABSENTISM: [3]MANPOWER!#REF!

Sheet INDEX
A1: CAM CALCULATION SHEET
A2: INDEX
A3: Area Summary
A4: Area Breakup - Mall
A5: Aarea Breakup- Office
A6: Area Breakup- Common Area
A7: Comm. Services
A8: CAM Variables
A9: CAM Charge Summary
A10: CAM Charge Calculation Sheet
A11: AMC Cost
A12: Common Electrical Load
... A19: Sinking Fund Calculation

Sheet Area Summary
A1: AREA STATEMENT | F1: INDEX
A2: BUILT-UP AREA STATEMENT
A4: PLOT AREA = 8082.16 Sq.m
B5: Actual areas
A7: Sr No. | B7: Description | C7: Built Up Area | D7: Leasable Area | E7: Air conditioned Area
A9: A | B9: Parking/Services
A10: 1 | B10: 2nd Basement | C10: 70796.981
A11: 2 | B11: 3rd Basement | C11: 70796.981
A12: 3 | B12: 4th Basement | C12: 70796.981
A13: 4 | B13: 1st Basement (MEP) | C13: 66168.891 | D13: =C13 -> 66168.891
C14: =SUM(C10:C13) -> 278559.83
A15: B | B15: Mall
A16: 2 | B16: Ground (Retail) | C16: ='Area-Mall'!F17 -> 35978.67 | D16: ='Area-Mall'!I17 -> 44426.57
A17: 3 | B17: L1(Retail) | C17: ='Area-Mall'!F28 -> 34642.858 | D17: ='Area-Mall'!I28 -> 46313.445
A18: 4 | B18: L2(Retail) | C18: ='Area-Mall'!F41 -> 36523.328 | D18: ='Area-Mall'!I41 -> 51865.354
A19: 5 | B19: L3(Food Court) | C19: 48631.752 | D19: ='Area-Mall'!I49 -> 44518
B20: Total Mall Area | C20: =SUM(C16:C19) -> 155776.61 | D20: =SUM(D16:D19) -> 187123.37 | E20: =D20*50%*90% -> 84205.516
A22: C | B22: Office
A24: 1 | B24: Office-L4 | C24: ='Area-Office'!F11 -> 46058.08 | D24: ='Area-Office'!I11 -> 58033.18
B25: Office-L5 | C25: ='Area-Office'!F20 -> 44248.651 | D25: ='Area-Office'!I20 -> 55753.301
B26: Office-L6 | C26: ='Area-Office'!F29 -> 46058.08 | D26: ='Area-Office'!I29 -> 58033.18
B27: Office-L7 | C27: ='Area-Office'!F37 -> 46058.08 | D27: ='Area-Office'!I37 -> 58033.18
B28: Office-L8 | C28: ='Area-Office'!F45 -> 46058.08 | D28: ='Area-Office'!I45 -> 58033.18
B29: Total Office Area | C29: =SUM(C25:C28) -> 182422.89 | D29: =SUM(D24:D28) -> 287886.02 | E29: =D29*70% -> 201520.22
B32: TOTAL B+C+D | D32: =D20+D29 -> 475009.39

Sheet Area-Mall
A1: AREA STATEMENT
A2: Sl. No. | B2: Description | C2: Carpet area | E2: Built up area | G2: Loading in % | H2: Super BUA/Saleable area | J2: efficiency | K2: f/d
C3: Sq m | D3: Sq ft | E3: Sq m | F3: Sq ft | G3: % | H3: Sq m | I3: Sq ft | J3: super / carpet
B4: Ground Floor Area
A5: 1 | B5: LG - 01 | C5: 107.3 | D5: 1154.9772 | E5: 115.9 | F5: 1247.5476 | G5: 0.62 | H5: 187.758 | I5: 2021.0271 | J5: =D5/I5 -> 0.57148031 | K5: =F5/D5 -> 1.0801491
A6: 2 | B6: LG – 02 | C6: 36.4 | D6: 391.8096 | E6: 40.3 | F6: 433.7892 | G6: 0.67 | H6: 67.301 | I6: 724.42796 | J6: =D6/I6 -> 0.54085378 | K6: =F6/D6 -> 1.1071429
A7: 3 | B7: LG - 03 | C7: 37.5 | D7: 403.65 | E7: 41.7 | F7: 448.8588 | G7: 0.67 | H7: 69.639 | I7: 749.5942 | J7: =D7/I7 -> 0.53849136 | K7: =F7/D7 -> 1.112
A8: 4 | B8: LG – 04- Anchor 01 | C8: 2244 | D8: 24154.416 | E8: 2285.9 | F8: 24605.428 | G8: 0.24 | H8: 2834.516 | I8: 30510.73 | J8: =D8/I8 -> 0.79166955 | K8: =F8/D8 -> 1.018672
A9: 5 | B9: LG - 05 | C9: 35.9 | D9: 386.4276 | E9: 39.2 | F9: 421.9488 | G9: 0.67 | H9: 65.464 | I9: 704.6545 | J9: =D9/I9 -> 0.54839301 | K9: =F9/D9 -> 1.091922
A10: 6 | B10: LG - 06 | C10: 61.8 | D10: 665.2152 | E10: 69 | F10: 742.716 | G10: 0.65 | H10: 113.85 | I10: 1225.4814 | J10: =D10/I10 -> 0.5428195 | K10: =F10/D10 -> 1.1165049
A11: 7 | B11: LG - 07 | C11: 63.1 | D11: 679.2084 | E11: 70.2 | F11: 755.6328 | G11: 0.65 | H11: 115.83 | I11: 1246.7941 | J11: =D11/I11 -> 0.54476388 | K11: =F11/D11 -> 1.1125198
A12: 8 | B12: LG - 08 | C12: 58.4 | D12: 628.6176 | E12: 63 | F12: 678.132 | G12: 0.65 | H12: 103.95 | I12: 1118.9178 | J12: =D12/I12 -> 0.56180856 | K12: =F12/D12 -> 1.0787671
A13: 9 | B13: LG - 09 | C13: 20.8 | D13: 223.8912 | E13: 23.3 | F13: 250.8012 | G13: 0.67 | H13: 38.911 | I13: 418.838 | J13: =D13/I13 -> 0.53455321 | K13: =F13/D13 -> 1.1201923
A14: 10 | B14: LG - 10 | C14: 58.7 | D14: 631.8468 | E14: 64.6 | F14: 695.3544 | G14: 0.65 | H14: 106.59 | I14: 1147.3348 | J14: =D14/I14 -> 0.55070832 | K14: =F14/D14 -> 1.1005111
A15: 11 | B15: LG - 11-1 | C15: 252.5 | D15: 2717.91 | E15: 264.7 | F15: 2849.2308 | G15: 0.6 | H15: 221.94352 | I15: 2389 | L15: Actual area sold (loading not done)
A16: 12 | B16: LG - 11-2 | C16: 252.5 | D16: 2717.91 | E16: 264.7 | F16: 2849.2308 | G16: 0.6 | H16: 201.57655 | I16: 2169.77 | J16: =D16/I16 -> 1.2526259 | K16: =F16/D16 -> 1.0483168 | L16: Actual area sold (loading not done)
B17: TOTAL | F17: =SUM(F5:F16) -> 35978.67 | H17: 4127.3291 | I17: 44426.57
B19: First Floor Area
A20: 1 | B20: L1 - 01 | C20: 146.4 | D20: 1575.8496 | E20: 155 | F20: 1668.42 | G20: 0.6 | H20: 248 | I20: 2669.472 | J20: =D20/I20 -> 0.59032258 | K20: =F20/D20 -> 1.0587432
A21: 2 | B21: L1 - 02 | C21: 58.7 | D21: 631.8468 | E21: 63.6 | F21: 684.5904 | G21: 0.65 | H21: 104.94 | I21: 1129.5742 | J21: =D21/I21 -> 0.55936726 | K21: =F21/D21 -> 1.0834753
A22: 3 | B22: L1 - 03 | C22: 28.8 | D22: 310.0032 | E22: 30.7 | F22: 330.4548 | G22: 0.67 | H22: 51.269 | I22: 551.85952 | J22: =D22/I22 -> 0.56174296 | K22: =F22/D22 -> 1.0659722
A23: 4 | B23: L1 - 04-Anchor 01 | C23: 2352 | D23: 25316.928 | E23: 2400 | F23: 25833.6 | G23: 0.24 | H23: 2976 | I23: 32033.664 | J23: =D23/I23 -> 0.79032258 | K23: =F23/D23 -> 1.0204082
A24: 5 | B24: L1 - 05 | C24: 80.3 | D24: 864.3492 | E24: 84.5 | F24: 909.558 | G24: 0.65 | H24: 139.425 | I24: 1500.7707 | J24: =D24/I24 -> 0.57593688 | K24: =F24/D24 -> 1.0523039
A25: 6 | B25: L1 - 06 | C25: 89.8 | D25: 966.6072 | E25: 96 | F25: 1033.344 | G25: 0.65 | H25: 158.4 | I25: 1705.0176 | J25: =D25/I25 -> 0.56691919 | K25: =F25/D25 -> 1.0690423
A26: 7 | B26: L1 - 07 | C26: 52.2 | D26: 561.8808 | E26: 56.6 | F26: 609.2424 | G26: 0.65 | H26: 93.39 | I26: 1005.25 | J26: =D26/I26 -> 0.55894635 | K26: =F26/D26 -> 1.0842912
A27: 8 | B27: L1 - 08 | C27: 316.3 | D27: 3404.6532 | E27: 332 | F27: 3573.648 | G27: 0.6 | H27: 531.2 | I27: 5717.8368 | J27: =D27/I27 -> 0.59544428 | K27: =F27/D27 -> 1.0496364
B28: TOTAL | F28: =SUM(F20:F27) -> 34642.858 | H28: 4302.624 | I28: 46313.445
B30: Second Floor Area
A31: 1 | B31: L2 - 01 | C31: 66.2 | D31: 712.5768 | E31: 72.6 | F31: 781.4664 | G31: 0.65 | H31: 119.79 | I31: 1289.4196 | J31: =D31/I31 -> 0.55263378 | K31: =F31/D31 -> 1.0966767
A32: 2 | B32: L2 - 02 | C32: 66.8 | D32: 719.0352 | E32: 72.3 | F32: 778.2372 | G32: 0.65 | H32: 119.295 | I32: 1284.0914 | J32: =D32/I32 -> 0.55995641 | K32: =F32/D32 -> 1.0823353
A33: 3 | B33: L2 - 03 | C33: 33.3 | D33: 358.4412 | E33: 37 | F33: 398.268 | G33: 0.67 | H33: 61.79 | I33: 665.10756 | J33: =D33/I33 -> 0.53892216 | K33: =F33/D33 -> 1.1111111
A34: 4 | B34: L2 - 04- Anchor 01 | C34: 1800.8 | D34: 19383.811 | E34: 1832.6 | F34: 19726.106 | G34: 0.28 | H34: 2345.728 | I34: 25249.416 | J34: =D34/I34 -> 0.76769344 | K34: =F34/D34 -> 1.0176588
A35: 5 | B35: L2 - 05 (kiosk) | C35: 16 | D35: 172.224 | E35: 19 | F35: 204.516 | G35: 0.67 | H35: 31.73 | I35: 341.54172 | J35: =D35/I35 -> 0.50425465 | K35: =F35/D35 -> 1.1875
A36: 6 | B36: L2 - 06 | C36: 96.7 | D36: 1040.8788 | E36: 102.6 | F36: 1104.3864 | G36: 0.65 | H36: 169.29 | I36: 1822.2376 | J36: =D36/I36 -> 0.57120917 | K36: =F36/D36 -> 1.0610134
A37: 7 | B37: L2- 07 | C37: 220.3 | D37: 2371.3092 | E37: 226.8 | F37: 2441.2752 | G37: 0.6 | H37: 362.88 | I37: 3906.0403 | J37: =D37/I37 -> 0.60708774 | K37: =F37/D37 -> 1.0295052
A38: 8 | B38: L2 - 08 | C38: 61.3 | D38: 659.8332 | E38: 66.2 | F38: 712.5768 | G38: 0.65 | H38: 109.23 | I38: 1175.7517 | J38: =D38/I38 -> 0.56120114 | K38: =F38/D38 -> 1.0799347
A39: 9 | B39: L2 – 09 | C39: 898.5 | D39: 9671.454 | E39: 926.7 | F39: 9974.9988 | G39: 0.55 | H39: 1436.385 | I39: 15461.248 | J39: =D39/I39 -> 0.62552867 | K39: =F39/D39 -> 1.0313856
A40: 10 | B40: L2 – 10 (kiosk) | C40: 34 | D40: 365.976 | E40: 37.3 | F40: 401.4972 | G40: 0.67 | H40: 62.291 | I40: 670.50032 | J40: =D40/I40 -> 0.54582524 | K40: =F40/D40 -> 1.0970588
B41: TOTAL | F41: =SUM(F31:F40) -> 36523.328 | H41: 4818.409 | I41: 51865.354
B43: Third Floor Area
...

Sheet Area-Office
A1: AREA STATEMENT- OFFICE
A2: Sl. No. | B2: Description | C2: Carpet area | E2: Built up area | G2: Loading in % | H2: Super BUA/Saleable area | J2: efficiency | K2: f/d
C3: Sq m | D3: Sq ft | E3: Sq m | F3: Sq ft | G3: % | H3: Sq m | I3: Sq ft | J3: super / carpet
B4: Fourth Floor
A5: 1 | B5: OFFICE-01 | C5: 1086.5 | D5: 11695.086 | E5: 1114.45 | F5: 11995.94 | G5: 0.26 | H5: 1404.207 | I5: 15114.884 | J5: =F5/I5 -> 0.79365079 | K5: =F5/D5 -> 1.0257248
A6: 2 | B6: OFFICE-02 | C6: 718.45 | D6: 7733.3958 | E6: 739.95 | F6: 7964.8218 | G6: 0.26 | H6: 932.337 | I6: 10035.675 | J6: =F6/I6 -> 0.79365079 | K6: =F6/D6 -> 1.0299255
A7: 3 | B7: OFFICE-03 | C7: 518.1 | D7: 5576.8284 | E7: 530.3 | F7: 5708.1492 | G7: 0.26 | H7: 668.178 | I7: 7192.268 | J7: =F7/I7 -> 0.79365079 | K7: =F7/D7 -> 1.0235476
A8: 4 | B8: OFFICE-04 | C8: 755 | D8: 8126.82 | E8: 778.3 | F8: 8377.6212 | G8: 0.26 | H8: 980.658 | I8: 10555.803 | J8: =F8/I8 -> 0.79365079 | K8: =F8/D8 -> 1.0308609
A9: 5 | B9: OFFICE-05 | C9: 589.35 | D9: 6343.7634 | E9: 604.5 | F9: 6506.838 | G9: 0.26 | H9: 761.67 | I9: 8198.6159 | J9: =F9/I9 -> 0.79365079 | K9: =F9/D9 -> 1.0257063
A10: 6 | B10: OFFICE-06 | C10: 492.52 | D10: 5301.4853 | E10: 511.4 | F10: 5504.7096 | G10: 0.26 | H10: 644.364 | I10: 6935.9341 | J10: =F10/I10 -> 0.79365079 | K10: =F10/D10 -> 1.0383335
B11: TOTAL | F11: =SUM(F5:F10) -> 46058.08 | H11: 5391.414 | I11: 58033.18
B13: Fifth Floor
A14: 1 | B14: OFFICE-01 | C14: 1086.5 | D14: 11695.086 | E14: 1114.45 | F14: 11995.94 | G14: 0.26 | H14: 1404.207 | I14: 15114.884 | J14: =F14/I14 -> 0.79365079 | K14: =F14/D14 -> 1.0257248
A15: 2 | B15: OFFICE-02 | C15: 706.45 | D15: 7604.2278 | E15: 735.45 | F15: 7916.3838 | G15: 0.26 | H15: 926.667 | I15: 9974.6436 | J15: =F15/I15 -> 0.79365079 | K15: =F15/D15 -> 1.0410503 | L15: Refuge area Reduction
A16: 3 | B16: OFFICE-03 | C16: 353.35 | D16: 3803.4594 | E16: 366.7 | F16: 3947.1588 | G16: 0.26 | H16: 462.042 | I16: 4973.4201 | J16: =F16/I16 -> 0.79365079 | K16: =F16/D16 -> 1.0377812 | L16: Refuge area Reduction
A17: 4 | B17: OFFICE-04 | C17: 755 | D17: 8126.82 | E17: 778.3 | F17: 8377.6212 | G17: 0.26 | H17: 980.658 | I17: 10555.803 | J17: =F17/I17 -> 0.79365079 | K17: =F17/D17 -> 1.0308609
A18: 5 | B18: OFFICE-05 | C18: 589.35 | D18: 6343.7634 | E18: 604.5 | F18: 6506.838 | G18: 0.26 | H18: 761.67 | I18: 8198.6159 | J18: =F18/I18 -> 0.79365079 | K18: =F18/D18 -> 1.0257063
A19: 6 | B19: OFFICE-06 | C19: 492.52 | D19: 5301.4853 | E19: 511.4 | F19: 5504.7096 | G19: 0.26 | H19: 644.364 | I19: 6935.9341 | J19: =F19/I19 -> 0.79365079 | K19: =F19/D19 -> 1.0383335
B20: TOTAL | F20: =SUM(F14:F19) -> 44248.651 | H20: 5179.608 | I20: 55753.301
B21: Sixth Floor
A22: 1 | B22: OFFICE-01 | C22: 1086.5 | D22: 11695.086 | E22: 1114.45 | F22: 11995.94 | G22: 0.26 | H22: 1404.207 | I22: 15114.884 | J22: =F22/I22 -> 0.79365079 | K22: =F22/D22 -> 1.0257248
A23: 2 | B23: OFFICE-02 | C23: 718.45 | D23: 7733.3958 | E23: 739.95 | F23: 7964.8218 | G23: 0.26 | H23: 932.337 | I23: 10035.675 | J23: =F23/I23 -> 0.79365079 | K23: =F23/D23 -> 1.0299255
A24: 3 | B24: OFFICE-03-1 | C24: 125.36 | D24: 1349.375 | E24: 128.3 | F24: 1381.0212 | G24: 0.26 | H24: 161.658 | I24: 1740.0867 | J24: =F24/I24 -> 0.79365079 | K24: =F24/D24 -> 1.0234525
A25: 4 | B25: OFFICE-03-2 | C25: 392.74 | D25: 4227.4534 | E25: 402 | F25: 4327.128 | G25: 0.26 | H25: 506.52 | I25: 5452.1813 | J25: =F25/I25 -> 0.79365079 | K25: =F25/D25 -> 1.0235779
A26: 5 | B26: OFFICE-04 | C26: 755 | D26: 8126.82 | E26: 778.3 | F26: 8377.6212 | G26: 0.26 | H26: 980.658 | I26: 10555.803 | J26: =F26/I26 -> 0.79365079 | K26: =F26/D26 -> 1.0308609
A27: 6 | B27: OFFICE-05 | C27: 589.35 | D27: 6343.7634 | E27: 604.5 | F27: 6506.838 | G27: 0.26 | H27: 761.67 | I27: 8198.6159 | J27: =F27/I27 -> 0.79365079 | K27: =F27/D27 -> 1.0257063
A28: 7 | B28: OFFICE-06 | C28: 492.52 | D28: 5301.4853 | E28: 511.4 | F28: 5504.7096 | G28: 0.26 | H28: 644.364 | I28: 6935.9341 | J28: =F28/I28 -> 0.79365079 | K28: =F28/D28 -> 1.0383335
B29: TOTAL | F29: =SUM(F22:F28) -> 46058.08 | H29: 5391.414 | I29: 58033.18
B30: Seventh Floor
A31: 1 | B31: OFFICE-01 | C31: 1086.5 | D31: 11695.086 | E31: 1114.45 | F31: 11995.94 | G31: 0.26 | H31: 1404.207 | I31: 15114.884 | J31: =F31/I31 -> 0.79365079 | K31: =F31/D31 -> 1.0257248
A32: 2 | B32: OFFICE-02 | C32: 718.45 | D32: 7733.3958 | E32: 739.95 | F32: 7964.8218 | G32: 0.26 | H32: 932.337 | I32: 10035.675 | J32: =F32/I32 -> 0.79365079 | K32: =F32/D32 -> 1.0299255
A33: 3 | B33: OFFICE-03 | C33: 518.1 | D33: 5576.8284 | E33: 530.3 | F33: 5708.1492 | G33: 0.26 | H33: 668.178 | I33: 7192.268 | J33: =F33/I33 -> 0.79365079 | K33: =F33/D33 -> 1.0235476
A34: 4 | B34: OFFICE-04 | C34: 755 | D34: 8126.82 | E34: 778.3 | F34: 8377.6212 | G34: 0.26 | H34: 980.658 | I34: 10555.803 | J34: =F34/I34 -> 0.79365079 | K34: =F34/D34 -> 1.0308609
A35: 5 | B35: OFFICE-05 | C35: 589.35 | D35: 6343.7634 | E35: 604.5 | F35: 6506.838 | G35: 0.26 | H35: 761.67 | I35: 8198.6159 | J35: =F35/I35 -> 0.79365079 | K35: =F35/D35 -> 1.0257063
A36: 6 | B36: OFFICE-06 | C36: 492.52 | D36: 5301.4853 | E36: 511.4 | F36: 5504.7096 | G36: 0.26 | H36: 644.364 | I36: 6935.9341 | J36: =F36/I36 -> 0.79365079 | K36: =F36/D36 -> 1.0383335
B37: TOTAL | F37: =SUM(F31:F36) -> 46058.08 | H37: 5391.414 | I37: 58033.18
B38: Eighth Floor
A39: 1 | B39: OFFICE-01 | C39: 1086.5 | D39: 11695.086 | E39: 1114.45 | F39: 11995.94 | G39: 0.26 | H39: 1404.207 | I39: 15114.884 | J39: =F39/I39 -> 0.79365079 | K39: =F39/D39 -> 1.0257248
A40: 2 | B40: OFFICE-02 | C40: 718.45 | D40: 7733.3958 | E40: 739.95 | F40: 7964.8218 | G40: 0.26 | H40: 932.337 | I40: 10035.675 | J40: =F40/I40 -> 0.79365079 | K40: =F40/D40 -> 1.0299255
A41: 3 | B41: OFFICE-03 | C41: 518.1 | D41: 5576.8284 | E41: 530.3 | F41: 5708.1492 | G41: 0.26 | H41: 668.178 | I41: 7192.268 | J41: =F41/I41 -> 0.79365079 | K41: =F41/D41 -> 1.0235476
...

Sheet Area-Comm
B1: AREA BREAKUP FOR COMMON AREA | R1: INDEX
B2: Common area components for each floor | C2: B4 | D2: B3 | E2: B2 | F2: B1 | G2: LG | H2: L1 | I2: L2 | J2: L3 | K2: L4 | L2: L5 | M2: L6 | N2: L7 | O2: L8 | P2: Total Sq Mtr | Q2: Total Sq ft
A4: Non AC | B4: Comm. Area | C4: =SUM(C5:C21) -> 745.8 | D4: =SUM(D5:D21) -> 451.17 | E4: =SUM(E5:E21) -> 451.7 | F4: =SUM(F5:F21) -> 2938 | G4: =SUM(G5:G21) -> 219.3 | H4: =SUM(H5:H21) -> 225.5 | I4: =SUM(I5:I21) -> 362.1 | J4: =SUM(J5:J21) -> 297.3 | ... P4: =SUM(P5:P21) -> 6551.53 | Q4: =P4*10.764 -> 70520.669
A5: Non AC | B5: Common Toilet | D5: 47 | F5: 70 | I5: 84.2 | J5: 80.4 | P5: =SUM(C5:O5) -> 281.6
A6: Non AC | B6: Services Area | C6: 276.7 | D6: 260.47 | E6: 308 | F6: 319 | G6: 73.5 | H6: 102 | I6: 157 | J6: 97 | K6: 57.5 | L6: 57.5 | M6: 57.5 | N6: 57.5 | O6: 57.5 | P6: =SUM(C6:O6) -> 1881.17
A7: Non AC | B7: Service Yard | F7: 554.6 | P7: =SUM(C7:O7) -> 554.6
A8: Non AC | B8: Electrical (HT/LT/Transformer/Panel) | F8: 619.1 | P8: =SUM(C8:O8) -> 619.1
A9: Non AC | B9: DG | F9: 264.4 | P9: =SUM(C9:O9) -> 264.4
A10: Non AC | B10: Plumbing and Fire fighting | F10: 197.3 | P10: =SUM(C10:O10) -> 197.3
A11: Non AC | B11: Fire fighting and CCTV control | F11: 48.4 | P11: =SUM(C11:O11) -> 48.4
A12: Non AC | B12: STP | C12: 325.4 | P12: =SUM(C12:O12) -> 325.4
A13: Non AC | B13: WTP | P13: =SUM(C13:O13) -> 0
A14: Non AC | B14: HVAC | F14: 692.3 | P14: =SUM(C14:O14) -> 692.3
A15: Non AC | B15: UPS and Battery | F15: 31.7 | P15: =SUM(C15:O15) -> 31.7
A16: Non AC | B16: ST-01 | C16: 28.8 | D16: 28.8 | E16: 28.8 | F16: 28.8 | G16: 24 | H16: 34.3 | I16: 29.3 | J16: 27 | K16: 28.14 | L16: 29.1 | M16: 28.14 | N16: 28.14 | O16: 28.14 | P16: =SUM(C16:O16) -> 371.46
A17: Non AC | B17: ST-02 | P17: =SUM(C17:O17) -> 0
A18: Non AC | B18: ST-03 | C18: 29.5 | D18: 29.5 | E18: 29.5 | F18: 27 | G18: 61 | H18: 28.4 | I18: 29.2 | J18: 29.2 | K18: 44.8 | L18: 26.5 | M18: 26.5 | N18: 26.5 | O18: 26.5 | P18: =SUM(C18:O18) -> 414.1
A19: Non AC | B19: ST-04 | C19: 30.4 | D19: 30.4 | E19: 30.4 | F19: 30.4 | G19: 30.4 | H19: 30.4 | I19: 30.4 | J19: 33.3 | K19: 25.74 | L19: 25.74 | M19: 25.74 | N19: 25.74 | O19: 25.74 | P19: =SUM(C19:O19) -> 374.8
A20: Non AC | B20: ST-05 | C20: 30.4 | D20: 30.4 | E20: 30.4 | F20: 30.4 | G20: 30.4 | H20: 30.4 | I20: 32 | J20: 30.4 | K20: 30.4 | L20: 30.4 | M20: 30.4 | N20: 30.4 | O20: 30.4 | P20: =SUM(C20:O20) -> 396.8
A21: Non AC | B21: ST-06 | C21: 24.6 | D21: 24.6 | E21: 24.6 | F21: 24.6 | P21: =SUM(C21:O21) -> 98.4
A23: Non AC | B23: Mall- Non AC | C23: =SUM(C24:C26) -> 45.8 | D23: =SUM(D24:D26) -> 45.8 | E23: =SUM(E24:E26) -> 45.8 | F23: =SUM(F24:F26) -> 56 | G23: =SUM(G24:G26) -> 56 | H23: =SUM(H24:H26) -> 56 | I23: =SUM(I24:I26) -> 56 | J23: =SUM(J24:J26) -> 33.6 | ... P23: =SUM(P24:P26) -> 395 | Q23: =P23*10.764 -> 4251.78
A24: Non AC | B24: Mall GE | C24: 16.8 | D24: 16.8 | E24: 16.8 | F24: 16.8 | G24: 16.8 | H24: 16.8 | I24: 16.8 | J24: 16.8 | P24: =SUM(C24:O24) -> 134.4
A25: Non AC | B25: Mall SE | C25: 16.8 | D25: 16.8 | E25: 16.8 | F25: 16.8 | G25: 16.8 | H25: 16.8 | I25: 16.8 | J25: 16.8 | P25: =SUM(C25:O25) -> 134.4
A26: Non AC | B26: Freight elevator | C26: 12.2 | D26: 12.2 | E26: 12.2 | F26: 22.4 | G26: 22.4 | H26: 22.4 | I26: 22.4 | P26: =SUM(C26:O26) -> 126.2
A27: Non AC | B27: Service lobby-Mall | G27: 104.3 | H27: 54.17 | I27: 56.14 | J27: 276.2 | P27: =SUM(C27:O27) -> 490.81
B28: Common Toilet-Mall | D28: 47 | F28: 70 | I28: 84.2 | J28: 80.4 | P28: =SUM(C28:O28) -> 281.6
A30: AC | B30: Mall- AC | C30: =SUM(C31:C33) -> 17 | D30: =SUM(D31:D33) -> 17 | E30: =SUM(E31:E33) -> 17 | F30: =SUM(F31:F33) -> 707.8 | G30: =SUM(G31:G33) -> 476 | H30: =SUM(H31:H33) -> 302 | I30: =SUM(I31:I33) -> 771.48 | J30: =SUM(J31:J33) -> 907.4 | ... P30: =SUM(P31:P33) -> 3215.68 | Q30: =P30*10.764 -> 34613.58
A31: AC | B31: Mall BOH | F31: 677.7 | P31: =SUM(C31:O31) -> 677.7
A32: AC | B32: Mall lobby | C32: 17 | D32: 17 | E32: 17 | F32: 30.1 | P32: =SUM(C32:O32) -> 81.1
A33: AC | B33: Corridor-Mall | G33: 476 | H33: 302 | I33: 771.48 | J33: 907.4 | P33: =SUM(C33:O33) -> 2456.88
A35: Non AC | B35: Office | C35: =SUM(C36:C39) -> 34.8 | D35: =SUM(D36:D39) -> 34.8 | E35: =SUM(E36:E39) -> 34.8 | F35: =SUM(F36:F39) -> 80.1 | G35: =SUM(G36:G39) -> 34.8 | H35: =SUM(H36:H39) -> 34.8 | I35: =SUM(I36:I39) -> 34.8 | J35: =SUM(J36:J39) -> 34.8 | ... O35: =SUM(O36:O39) -> 64.3 | P35: =SUM(P36:P38) -> 603.4 | Q35: =P35*10.764 -> 6494.9976 | S35: =Q35+Q41 -> 8982.0198
A36: Non AC | B36: Office GE | C36: 26.1 | D36: 26.1 | E36: 26.1 | F36: 26.1 | G36: 26.1 | H36: 26.1 | I36: 26.1 | J36: 26.1 | K36: 26.1 | L36: 26.1 | M36: 26.1 | N36: 26.1 | O36: 26.1 | P36: =SUM(C36:O36) -> 339.3
A37: Non AC | B37: Office SE | C37: 8.7 | D37: 8.7 | E37: 8.7 | F37: 8.7 | G37: 8.7 | H37: 8.7 | I37: 8.7 | J37: 8.7 | K37: 8.7 | L37: 8.7 | M37: 8.7 | N37: 8.7 | O37: 8.7 | P37: =SUM(C37:O37) -> 113.1
A38: Non AC | B38: Refuge Area | L38: 151 | P38: =SUM(C38:O38) -> 151
A39: Non AC | B39: Service lobby-Office | F39: 45.3 | K39: 29.5 | L39: 29.5 | M39: 29.5 | N39: 29.5 | O39: 29.5
A41: AC | B41: Office lobby | C41: =SUM(C42:C43) -> 24.35 | D41: =SUM(D42:D43) -> 24.35 | E41: =SUM(E42:E43) -> 24.35 | F41: =SUM(F42:F43) -> 42 | G41: =SUM(G42:G43) -> 116 | H41: =SUM(H42:H43) -> 0 | I41: =SUM(I42:I43) -> 0 | J41: =SUM(J42:J43) -> 0 | ... P41: =SUM(P42:P43) -> 231.05 | Q41: =P41*10.764 -> 2487.0222
A42: AC | B42: Office lobby | C42: 24.35 | D42: 24.35 | E42: 24.35 | F42: 42 | G42: 116 | P42: =SUM(C42:O42) -> 231.05
A43: AC | B43: Corridor-Office | K43: 228 | L43: 271.8 | M43: 228 | N43: 228 | O43: 228
P45: =SUM(P4,P23,P30,P35,P41) -> 10996.66 | Q45: =SUM(Q4,Q23,Q30,Q35,Q41) -> 118368.05

Sheet Common Services
A1: MAJOR COST HEADS FOR COMMON AREA CHARGES | E1: INDEX
A2: 1 | B2: Property Managenent Charges | C2: Property Management Company Servcies Charges
C3: Management Establishment Cost
A4: 2 | B4: Engineering Services / Spares and Consumables / AMC | C4: Engineering Manpower
C5: Spares and Consumables
C6: General Maintenance tools ( Amortized Cost)
C7: AMC Charges
A8: 3 | B8: Utility Cost ( Electricity , Air conditioning and Water) | C8: Common Area Equipments / Lighting etc
C9: Common Area Airconditioning Cost
C10: Cost of water
A11: 5 | B11: Janitorial / Gardening / Pest Control/ Security | C11: Housekeeping Manpower
C12: Housekeeping Equipments
C13: Housekeeping Cleaning Consumables and Toiletries
C14: Housekeeping Toiletries
C15: Horticulture Manpower
C16: Horticulture Tools and Consumables
C17: Pest Control Services
C18: Waste Management System
C19: Façade Cleaning Services
C20: Security Manpower Costing
A21: 6 | B21: Liosaning, Licenses and Audit Cost | C21: Electrical and DG License renewal
C22: Lift License Renewal
C23: Fire NOC
C24: STP CTO
C25: Labour license and registration
C26: Liosaning & Licenses Cost
C27: Environmental and Pollution Control Inspections
A28: 7 | B28: Miscellaneous Costs | C28: Rental Equipment (Pumps / Ladders etc)
C29: Travel / Conveyance / Hire Charges Of taxi / cabs
C30: Office Stationary and Printed Stationary
C31: Site Team Communication Charges-Mobile
C32: Mangzine, Journals and Newspapers
C33: TV Cable Connection
C34: Staff Welfare for deployed manpower ( CW & Sub Contractor)
C35: Events and Festivel Expenses ( Decoration, Sweets, Consumables)
C36: Courier Charges
C37: Staff Uniforms
C38: C&W administration cost for misc. expenses
A39: 8 | B39: Audits | C39: Energy Audit / Thermography and Harmonic Test
C40: Financial Audit
...

Sheet CAM Variables
A1: CAM Variables-
A2: Variable 1 | F2: Mall Leasablke Area in sq ft | G2: ='Area Summary'!D20 -> 187123.37 | I2: INDEX
F3: Office Space leasable area in sq ft | G3: ='Area Summary'!D29 -> 287886.02 | J3: =G2+G3 -> 475009.39
A5: Variable 2 | B5: Power Supply Details
D6: DG Set Supply | F6: EB Supply
B7: Rates estimated for FY 14-15 | D7: Rate | E7: 64 | F7: Fixed Charges ( KVA) | G7: 350
D8: Unit per Ltrs. | E8: 3.5 | F8: Unit Rate ( KVAH) | G8: 6.5
D9: Cost per Unit | E9: =ROUND(E7/E8,2) -> 18.29 | F9: Power Breakdown in hrs | G9: 1.5
D10: Operation % | E10: =G9/24 -> 0.0625 | F10: Operation % | G10: =(24-G9)/24 -> 0.9375
A12: Variable 3 | B12: Minimum Wages Category | F12: Basic | G12: VDA
B13: Current Minimum wages rates | E13: Skilled | F13: 8079 | G13: 1739
E14: Semiskilled | F14: 6579 | G14: 1419
E15: Unskilled | F15: 5579 | G15: 1199

Sheet CAM Charges Summary
A1: CAM CHARGE CALCULATION BASED ON BUILT UP AREA | D1: 1st Year | H1: 2nd Year | L1: 3rd Year | O1: INDEX
D2: Mall | F2: Office | H2: Mall | J2: Office | L2: Mall | N2: Office
B3: AREA IN SQ. FT | D3: CAM / sq ft | F3: CAM / sq ft | H3: CAM / sq ft | J3: CAM / sq ft | L3: CAM / sq ft | N3: CAM / sq ft
B4: CAM COST PER MONTH PER SQ FT IN INR | D4: =SUM(D6,D8,D10,D12,D14,D16,D18,D20,D22) -> 13.32221 | F4: =SUM(F6,F8,F10,F12,F14,F16,F18,F20,F22) -> 9.9673078 | H4: =SUM(H6,H8,H10,H12,H14,H16,H18,H20,H22) -> 14.723316 | J4: =SUM(J6,J8,J10,J12,J14,J16,J18,J20,J22) -> 11.773246 | L4: =SUM(L6,L8,L10,L12,L14,L16,L18,L20,L22) -> 16.834874 | N4: =SUM(N6,N8,N10,N12,N14,N16,N18,N20,N22) -> 13.285133
A6: 1 | B6: Manpower Cost | D6: ='CAM Charges'!I8 -> 7.538619 | F6: ='CAM Charges'!M8 -> 5.2125856 | H6: ='CAM Charges'!T8 -> 8.2924809 | J6: ='CAM Charges'!X8 -> 5.7338442 | L6: ='CAM Charges'!AE8 -> 9.121729 | N6: ='CAM Charges'!AI8 -> 6.3072286
A8: 2 | B8: Spares and Consumables ( Engineering & Building Services) | D8: ='CAM Charges'!I19 -> 0.89448424 | F8: ='CAM Charges'!M19 -> 0.75263651 | H8: ='CAM Charges'!T19 -> 0.95074193 | J8: ='CAM Charges'!X19 -> 0.80180182 | L8: ='CAM Charges'!AE19 -> 0.98748713 | N8: ='CAM Charges'!AI19 -> 0.83110002
A10: 3 | B10: AMC Charges | D10: ='CAM Charges'!I26 -> 0 | F10: ='CAM Charges'!M26 -> 0 | H10: ='CAM Charges'!T26 -> 0.26961572 | J10: ='CAM Charges'!X26 -> 0.90644183 | L10: ='CAM Charges'!AE26 -> 1.1752477 | N10: ='CAM Charges'!AI26 -> 1.515923
A12: 4 | B12: Electricity Cost ( Utility & Common Area HVAC) | D12: ='CAM Charges'!I28 -> 1.6797 | F12: ='CAM Charges'!M28 -> 1.2593082 | H12: ='CAM Charges'!T28 -> 1.763685 | J12: ='CAM Charges'!X28 -> 1.3222736 | L12: ='CAM Charges'!AE28 -> 1.8518693 | N12: ='CAM Charges'!AI28 -> 1.3883873
A14: 5 | B14: Audits | D14: ='CAM Charges'!I32 -> 0.091226267 | F14: ='CAM Charges'!M32 -> 0.091226267 | H14: ='CAM Charges'!T32 -> 0.12806764 | J14: ='CAM Charges'!X32 -> 0.12806764 | L14: ='CAM Charges'!AE32 -> 0.12806764 | N14: ='CAM Charges'!AI32 -> 0.12806764
A16: 6 | B16: Liosaning & Licenses Cost | D16: ='CAM Charges'!I40 -> 0.079770353 | F16: ='CAM Charges'!M40 -> 0.079770353 | H16: ='CAM Charges'!T40 -> 0.078717742 | J16: ='CAM Charges'!X40 -> 0.078717742 | L16: ='CAM Charges'!AE40 -> 0.078717742 | N16: ='CAM Charges'!AI32 -> 0.12806764
A18: 7 | B18: Administrative Expenses | D18: ='CAM Charges'!I51 -> 0.14799707 | F18: ='CAM Charges'!M51 -> 0.14799707 | H18: ='CAM Charges'!T51 -> 0.16483885 | J18: ='CAM Charges'!X51 -> 0.16483885 | L18: ='CAM Charges'!AE51 -> 0.16483885 | N18: ='CAM Charges'!AI51 -> 0.16483885
A20: 8 | B20: Insurance, Sinking Fund | D20: ='CAM Charges'!I62 -> 1.4569431 | F20: ='CAM Charges'!M62 -> 1.4569431 | H20: ='CAM Charges'!T62 -> 1.5032069 | J20: ='CAM Charges'!X62 -> 1.5032069 | L20: ='CAM Charges'!AE62 -> 1.5513213 | N20: ='CAM Charges'!AI62 -> 1.5513213
A22: 9 | B22: Profit Margin 10% on Actual Expense | D22: ='CAM Charges'!I68 -> 1.4334702 | F22: ='CAM Charges'!M68 -> 0.96684071 | H22: ='CAM Charges'!T68 -> 1.5719615 | J22: ='CAM Charges'!X68 -> 1.134053 | L22: ='CAM Charges'!AE68 -> 1.7755951 | N22: ='CAM Charges'!AI68 -> 1.2701988

Sheet CAM Charges
A1: PROPOSED CAM CHARGES
A2: CAM CHARGE CALCULATION BASED ON BUILT UP AREA OF | D2: 1st Year | O2: 2nd Year | Z2: 3rd Year | AK2: INDEX
D3: Combined Services | G3: Mall | K3: Office Area | O3: Combined Services | R3: Mall | V3: Office Area | Z3: Combined Services | AC3: Mall | AG3: Office Area
B4: AREA IN SQ. FT | D4: Area sft | E4: ='CAM Variables'!J3 -> 475009.39 | G4: Area sft | H4: ='CAM Variables'!G2 -> 187123.37 | I4: CAM rate | K4: Area sft | L4: ='CAM Variables'!G3 -> 287886.02 | M4: CAM rate | O4: Area sft | P4: =E4 -> 475009.39 | R4: Area sft | S4: =H4 -> 187123.37 | T4: CAM rate | V4: Area sft | W4: =L4 -> 287886.02 | X4: CAM rate | Z4: Area sft | AA4: =P4 -> 475009.39 | AC4: Area sft | AD4: =S4 -> 187123.37 | AE4: CAM rate | AG4: Area sft | AH4: =W4 -> 287886.02 | AI4: CAM rate
B5: CAM COST PER MONTH IN INR | D5: Monthly Cost | E5: =SUM(D8,D19,D26,D28,D32,D40,D51,D62,D68) -> 3888670.3 | G5: Monthly Cost | H5: =SUM(G8,G19,G26,G28,G32,G40,G51,G62,G68) -> 1418705.7 | I5: =SUM(I8,I19,I26,I28,I32,I40,I51,I62,I68) -> 13.32221 | K5: Monthly Cost | L5: =SUM(K8,K19,K26,K28,K32,K40,K51,K62,K68) -> 704956.7 | M5: =SUM(M8,M19,M26,M28,M32,M40,M51,M62,M68) -> 9.9673078 | O5: Monthly Cost | P5: =SUM(O8,O19,O26,O28,O32,O40,O51,O62,O68) -> 4357603.3 | R5: Monthly Cost | S5: =SUM(R8,R19,R26,R28,R32,R40,R51,R62,R68) -> 1519040.5 | T5: =SUM(T8,T19,T26,T28,T32,T40,T51,T62,T68) -> 14.723316 | V5: Monthly Cost | W5: =SUM(V8,V19,V26,V28,V32,V40,V51,V62,V68) -> 950272.09 | X5: =SUM(X8,X19,X26,X28,X32,X40,X51,X62,X68) -> 11.773246 | Z5: Monthly Cost | AA5: =SUM(Z8,Z19,Z26,Z28,Z32,Z40,Z51,Z62,Z68) -> 4976847.4 | AC5: Monthly Cost | AD5: =SUM(AC8,AC19,AC26,AC28,AC32,AC40,AC51,AC62,AC68) -> 1694248.7 | AE5: =SUM(AE8,AE19,AE26,AE28,AE32,AE40,AE51,AE62,AE68) -> 16.834874 | AG5: Monthly Cost | AH5: =SUM(AG8,AG19,AG26,AG28,AG32,AG40,AG51,AG62,AG68) -> 1006110 | AI5: =SUM(AI8,AI19,AI26,AI28,AI32,AI40,AI51,AI62,AI68) -> 13.235783
A6: CAM Charges INR/ Per sq ft / month | D6: per sq. ft cost | E6: =SUM(E8,E19,E26,E28,E32,E40,E51,E62,E68) -> 8.1903459 | G6: per sq. ft cost | H6: =SUM(H8,H19,H26,H28,H32,H40,H51,H62,H68) -> 5.1356979 | K6: per sq. ft cost | L6: =SUM(L8,L19,L26,L28,L32,L40,L51,L62,L68) -> 1.7807954 | O6: per sq. ft cost | P6: =SUM(P8,P19,P26,P28,P32,P40,P51,P62,P68) -> 9.1676069 | R6: per sq. ft cost | S6: =SUM(S8,S19,S26,S28,S32,S40,S51,S62,S68) -> 5.5495959 | V6: per sq. ft cost | W6: =SUM(W8,W19,W26,W28,W32,W40,W51,W62,W68) -> 2.5995252 | Z6: per sq. ft cost | AA6: =SUM(AA8,AA19,AA26,AA28,AA32,AA40,AA51,AA62,AA68) -> 10.473139 | AC6: per sq. ft cost | AD6: =SUM(AD8,AD19,AD26,AD28,AD32,AD40,AD51,AD62,AD68) -> 6.3575074 | AG6: per sq. ft cost | AH6: =SUM(AH8,AH19,AH26,AH28,AH32,AH40,AH51,AH62,AH68) -> 2.7584168
A8: 1 | B8: Manpower Cost | D8: =SUM(D9:D17) -> 2224001.8 | E8: =SUM(E9:E17) -> 4.6820165 | G8: =SUM(G10:G17) -> 534537.1 | H8: =SUM(H10:H17) -> 2.8566026 | I8: =SUM(I9:I17) -> 7.538619 | K8: =SUM(K10:K17) -> 152743.45 | L8: =SUM(L10:L17) -> 0.53056918 | M8: =SUM(M9:M17) -> 5.2125856 | O8: =SUM(O9:O17) -> 2446402 | P8: =SUM(P9:P17) -> 5.1502181 | R8: =SUM(R10:R17) -> 587990.81 | S8: =SUM(S10:S17) -> 3.1422628 | T8: =SUM(T9:T17) -> 8.2924809 | V8: =SUM(V10:V17) -> 168017.8 | W8: =SUM(W10:W17) -> 0.5836261 | X8: =SUM(X9:X17) -> 5.7338442 | Z8: =SUM(Z9:Z17) -> 2691042.2 | AA8: =SUM(AA9:AA17) -> 5.6652399 | AC8: =SUM(AC10:AC17) -> 646789.89 | AD8: =SUM(AD10:AD17) -> 3.4564891 | AE8: =SUM(AE9:AE17) -> 9.121729 | AG8: =SUM(AG10:AG17) -> 184819.57 | AH8: =SUM(AH10:AH17) -> 0.64198871 | AI8: =SUM(AI9:AI17) -> 6.3072286
A9: a | B9: Manpower Cost | D9: =Manpower!M8 -> 180000 | E9: =D9/$E$4 -> 0.37893988 | G9: 0 | H9: =G9/$H$4 -> 0 | I9: =E9+H9 -> 0.37893988 | L9: =K9/$L$4 -> 0 | M9: =E9+L9 -> 0.37893988 | O9: =D9*110% -> 198000 | P9: =O9/$E$4 -> 0.41683386 | R9: =G9*110% -> 0 | S9: =R9/$H$4 -> 0 | T9: =P9+S9 -> 0.41683386 | V9: =K9*110% -> 0 | W9: =V9/$L$4 -> 0 | X9: =P9+W9 -> 0.41683386 | Z9: =O9*110% -> 217800 | AA9: =Z9/$E$4 -> 0.45851725 | AC9: =R9*110% -> 0 | AD9: =AC9/$H$4 -> 0 | AE9: =AA9+AD9 -> 0.45851725 | AG9: =V9*110% -> 0 | AH9: =AG9/$L$4 -> 0 | AI9: =AA9+AH9 -> 0.45851725
A10: b | B10: Management Staff | D10: =Manpower!M20 -> 495833.33 | E10: =D10/$E$4 -> 1.043839 | G10: 0 | H10: =G10/$H$4 -> 0 | I10: =E10+H10 -> 1.043839 | K10: =G10*110% -> 0 | L10: =K10/$L$4 -> 0 | M10: =E10+L10 -> 1.043839 | O10: =D10*110% -> 545416.67 | P10: =O10/$E$4 -> 1.1482229 | R10: =G10*110% -> 0 | S10: =R10/$H$4 -> 0 | T10: =P10+S10 -> 1.1482229 | V10: =K10*110% -> 0 | W10: =V10/$L$4 -> 0 | X10: =P10+W10 -> 1.1482229 | Z10: =O10*110% -> 599958.33 | AA10: =Z10/$E$4 -> 1.2630452 | AC10: =R10*110% -> 0 | AD10: =AC10/$H$4 -> 0 | AE10: =AA10+AD10 -> 1.2630452 | AG10: =V10*110% -> 0 | AH10: =AG10/$L$4 -> 0 | AI10: =AA10+AH10 -> 1.2630452
A11: c | B11: Property Management Fee- IPC | D11: 225000 | E11: =D11/$E$4 -> 0.47367485 | G11: 0 | H11: =G11/$H$4 -> 0 | I11: =E11+H11 -> 0.47367485 | K11: =G11*110% -> 0 | L11: =K11/$L$4 -> 0 | M11: =E11+L11 -> 0.47367485 | O11: =D11*110% -> 247500 | P11: =O11/$E$4 -> 0.52104233 | R11: =G11*110% -> 0 | S11: =R11/$H$4 -> 0 | T11: =P11+S11 -> 0.52104233 | V11: =K11*110% -> 0 | W11: =V11/$L$4 -> 0 | X11: =P11+W11 -> 0.52104233 | Z11: =O11*110% -> 272250 | AA11: =Z11/$E$4 -> 0.57314656 | AC11: =R11*110% -> 0 | AD11: =AC11/$H$4 -> 0 | AE11: =AA11+AD11 -> 0.57314656 | AG11: =V11*110% -> 0 | AH11: =AG11/$L$4 -> 0 | AI11: =AA11+AH11 -> 0.57314656
A12: d | B12: Engineering Manpower | D12: =Manpower!M33 -> 572810 | E12: =D12/$E$4 -> 1.2058919 | G12: 0 | H12: =G12/$H$4 -> 0 | I12: =E12+H12 -> 1.2058919 | K12: =G12*110% -> 0 | L12: =K12/$L$4 -> 0 | M12: =E12+L12 -> 1.2058919 | O12: =D12*110% -> 630091 | P12: =O12/$E$4 -> 1.3264811 | R12: =G12*110% -> 0 | S12: =R12/$H$4 -> 0 | T12: =P12+S12 -> 1.3264811 | V12: =K12*110% -> 0 | W12: =V12/$L$4 -> 0 | X12: =P12+W12 -> 1.3264811 | Z12: =O12*110% -> 693100.1 | AA12: =Z12/$E$4 -> 1.4591293 | AC12: =R12*110% -> 0 | AD12: =AC12/$H$4 -> 0 | AE12: =AA12+AD12 -> 1.4591293 | AG12: =V12*110% -> 0 | AH12: =AG12/$L$4 -> 0 | AI12: =AA12+AH12 -> 1.4591293
A13: e | B13: Custodial Services Manpower | D13: =Manpower!M40 -> 132704.45 | E13: =D13/$E$4 -> 0.27937227 | G13: =Manpower!M45 -> 303957.1 | H13: =G13/$H$4 -> 1.6243674 | I13: =E13+H13 -> 1.9037397 | K13: =Manpower!M49 -> 95098.45 | L13: =K13/$L$4 -> 0.33033368 | M13: =E13+L13 -> 0.60970595 | O13: =D13*110% -> 145974.9 | P13: =O13/$E$4 -> 0.30730949 | R13: =G13*110% -> 334352.81 | S13: =R13/$H$4 -> 1.7868041 | T13: =P13+S13 -> 2.0941136 | V13: =K13*110% -> 104608.29 | W13: =V13/$L$4 -> 0.36336705 | X13: =P13+W13 -> 0.67067654 | Z13: =O13*110% -> 160572.38 | AA13: =Z13/$E$4 -> 0.33804044 | AC13: =R13*110% -> 367788.09 | AD13: =AC13/$H$4 -> 1.9654845 | AE13: =AA13+AD13 -> 2.303525 | AG13: =V13*110% -> 115069.12 | AH13: =AG13/$L$4 -> 0.39970376 | AI13: =AA13+AH13 -> 0.7377442
A14: f | B14: Horticulture Manpower | D14: =Manpower!M53 -> 45648 | E14: =D14/$E$4 -> 0.096099153 | G14: 0 | H14: =G14/$H$4 -> 0 | I14: =E14+H14 -> 0.096099153 | K14: 0 | L14: =K14/$L$4 -> 0 | M14: =E14+L14 -> 0.096099153 | O14: =D14*110% -> 50212.8 | P14: =O14/$E$4 -> 0.10570907 | R14: =G14*110% -> 0 | S14: =R14/$H$4 -> 0 | T14: =P14+S14 -> 0.10570907 | V14: =K14*110% -> 0 | W14: =V14/$L$4 -> 0 | X14: =P14+W14 -> 0.10570907 | Z14: =O14*110% -> 55234.08 | AA14: =Z14/$E$4 -> 0.11627997 | AC14: =R14*110% -> 0 | AD14: =AC14/$H$4 -> 0 | AE14: =AA14+AD14 -> 0.11627997 | AG14: =V14*110% -> 0 | AH14: =AG14/$L$4 -> 0 | AI14: =AA14+AH14 -> 0.11627997
A15: g | B15: Pest Control Services | D15: =100000*20/100 -> 20000 | E15: =D15/$E$4 -> 0.042104431 | G15: 0 | H15: =G15/$H$4 -> 0 | I15: =E15+H15 -> 0.042104431 | K15: 0 | L15: =K15/$L$4 -> 0 | M15: =E15+L15 -> 0.042104431 | O15: =D15*110% -> 22000 | P15: =O15/$E$4 -> 0.046314874 | R15: =G15*110% -> 0 | S15: =R15/$H$4 -> 0 | T15: =P15+S15 -> 0.046314874 | V15: =K15*110% -> 0 | W15: =V15/$L$4 -> 0 | X15: =P15+W15 -> 0.046314874 | Z15: =O15*110% -> 24200 | AA15: =Z15/$E$4 -> 0.050946361 | AC15: =R15*110% -> 0 | AD15: =AC15/$H$4 -> 0 | AE15: =AA15+AD15 -> 0.050946361 | AG15: =V15*110% -> 0 | AH15: =AG15/$L$4 -> 0 | AI15: =AA15+AH15 -> 0.050946361
A16: h | B16: Façade Cleaning Services | D16: =Manpower!M84 -> 84952 | E16: =D16/$E$4 -> 0.17884278 | H16: =G16/$H$4 -> 0 | I16: =E16+H16 -> 0.17884278 | L16: =K16/$L$4 -> 0 | M16: =E16+L16 -> 0.17884278 | O16: =D16*110% -> 93447.2 | P16: =O16/$E$4 -> 0.19672706 | S16: =R16/$H$4 -> 0 | T16: =P16+S16 -> 0.19672706 | W16: =V16/$L$4 -> 0 | X16: =P16+W16 -> 0.19672706 | Z16: =O16*110% -> 102791.92 | AA16: =Z16/$E$4 -> 0.21639976 | AD16: =AC16/$H$4 -> 0 | AE16: =AA16+AD16 -> 0.21639976 | AH16: =AG16/$L$4 -> 0 | AI16: =AA16+AH16 -> 0.21639976
A17: i | B17: Security Services-manpower | D17: =Manpower!M68 -> 467054 | E17: =D17/$E$4 -> 0.98325214 | G17: =Manpower!M73 -> 230580 | H17: =G17/$H$4 -> 1.2322352 | I17: =E17+H17 -> 2.2154873 | K17: =Manpower!M76 -> 57645 | L17: =K17/$L$4 -> 0.20023549 | M17: =E17+L17 -> 1.1834876 | O17: =D17*110% -> 513759.4 | P17: =O17/$E$4 -> 1.0815774 | R17: =G17*110% -> 253638 | S17: =R17/$H$4 -> 1.3554587 | T17: =P17+S17 -> 2.4370361 | V17: =K17*110% -> 63409.5 | W17: =V17/$L$4 -> 0.22025904 | X17: =P17+W17 -> 1.3018364 | Z17: =O17*110% -> 565135.34 | AA17: =Z17/$E$4 -> 1.1897351 | AC17: =R17*110% -> 279001.8 | AD17: =AC17/$H$4 -> 1.4910046 | AE17: =AA17+AD17 -> 2.6807397 | AG17: =V17*110% -> 69750.45 | AH17: =AG17/$L$4 -> 0.24228495 | AI17: =AA17+AH17 -> 1.43202
A19: 2 | B19: Spares and Consumables ( Engineering & Building Services) | D19: =SUM(D20:D24) -> 324620.2 | E19: =SUM(E20:E24) -> 0.68339744 | G19: =SUM(G20:G24) -> 100268.21 | H19: =SUM(H20:H24) -> 0.2110868 | I19: =SUM(I20:I24) -> 0.89448424 | K19: =SUM(K20:K24) -> 32889.212 | L19: =SUM(L20:L24) -> 0.069239077 | M19: =SUM(M20:M24) -> 0.75263651 | O19: =SUM(O20:O24) -> 346329.72 | P19: =SUM(P20:P24) -> 0.72910079 | R19: =SUM(R20:R24) -> 105281.62 | S19: =SUM(S20:S24) -> 0.22164114 | T19: =SUM(T20:T24) -> 0.95074193 | V19: =SUM(V20:V24) -> 34533.672 | W19: =SUM(W20:W24) -> 0.072701031 | X19: =SUM(X20:X24) -> 0.80180182 | Z19: =SUM(Z20:Z24) -> 358519.96 | AA19: =SUM(AA20:AA24) -> 0.75476393 | AC19: =SUM(AC20:AC24) -> 110545.7 | AD19: =SUM(AD20:AD24) -> 0.2327232 | AE19: =SUM(AE20:AE24) -> 0.98748713 | AG19: =SUM(AG20:AG24) -> 36260.356 | AH19: =SUM(AH20:AH24) -> 0.076336083 | AI19: =SUM(AI20:AI24) -> 0.83110002
A20: a | B20: Engineering Spares and Consumables | D20: =265119*80% -> 212095.2 | E20: =D20/$E$4 -> 0.44650738 | G20: 80768.212 | H20: =G20/$E$4 -> 0.17003498 | I20: =E20+H20 -> 0.61654236 | K20: 23389.212 | L20: =K20/$E$4 -> 0.049239473 | M20: =E20+L20 -> 0.49574686 | O20: =D20*110% -> 233304.72 | P20: =O20/$E$4 -> 0.49115812 | R20: =G20*105% -> 84806.623 | S20: =R20/$E$4 -> 0.17853673 | T20: =P20+S20 -> 0.66969485 | V20: =K20*105% -> 24558.672 | W20: =V20/$E$4 -> 0.051701446 | X20: =P20+W20 -> 0.54285957 | Z20: =O20*105% -> 244969.96 | AA20: =Z20/$E$4 -> 0.51571603 | AC20: =R20*105% -> 89046.954 | AD20: =AC20/$E$4 -> 0.18746357 | AE20: =AA20+AD20 -> 0.70317959 | AG20: =V20*105% -> 25786.606 | AH20: =AG20/$E$4 -> 0.054286519 | AI20: =AA20+AH20 -> 0.57000255
A21: b | B21: Housekeeping Equipments | D21: ='HK - Secr Equipments'!J14 -> 30525 | E21: =D21/$E$4 -> 0.064261887 | H21: =G21/$E$4 -> 0 | I21: =E21+H21 -> 0.064261887 | L21: =K21/$E$4 -> 0 | M21: =E21+L21 -> 0.064261887 | O21: =D21 -> 30525 | P21: =O21/$E$4 -> 0.064261887 | R21: =G21 -> 0 | S21: =R21/$E$4 -> 0 | T21: =P21+S21 -> 0.064261887 | V21: =K21 -> 0 | W21: =V21/$E$4 -> 0 | X21: =P21+W21 -> 0.064261887 | Z21: =O21 -> 30525 | AA21: =Z21/$E$4 -> 0.064261887 | AC21: =R21 -> 0 | AD21: =AC21/$E$4 -> 0 | AE21: =AA21+AD21 -> 0.064261887 | AG21: =V21 -> 0 | AH21: =AG21/$E$4 -> 0 | AI21: =AA21+AH21 -> 0.064261887
A22: c | B22: Housekeeping Consumables and Toiletries | D22: 10000 | E22: =D22/$E$4 -> 0.021052215 | G22: 19500 | H22: =G22/$E$4 -> 0.04105182 | I22: =E22+H22 -> 0.062104035 | K22: 9500 | L22: =K22/$E$4 -> 0.019999605 | M22: =E22+L22 -> 0.04105182 | O22: =D22*105% -> 10500 | P22: =O22/$E$4 -> 0.022104826 | R22: =G22*105% -> 20475 | S22: =R22/$E$4 -> 0.043104411 | T22: =P22+S22 -> 0.065209237 | V22: =K22*105% -> 9975 | W22: =V22/$E$4 -> 0.020999585 | X22: =P22+W22 -> 0.043104411 | Z22: =O22*105% -> 11025 | AA22: =Z22/$E$4 -> 0.023210067 | AC22: =R22*105% -> 21498.75 | AD22: =AC22/$E$4 -> 0.045259632 | AE22: =AA22+AD22 -> 0.068469699 | AG22: =V22*105% -> 10473.75 | AH22: =AG22/$E$4 -> 0.022049564 | AI22: =AA22+AH22 -> 0.045259632
A23: f | B23: Horticulture Tools and Consumables | D23: =Manpower!M58 -> 29000 | E23: =D23/$E$4 -> 0.061051425 | H23: =G23/$E$4 -> 0 | I23: =E23+H23 -> 0.061051425 | L23: =K23/$E$4 -> 0 | M23: =E23+L23 -> 0.061051425 | O23: =D23 -> 29000 | P23: =O23/$E$4 -> 0.061051425 | R23: =G23 -> 0 | S23: =R23/$E$4 -> 0 | T23: =P23+S23 -> 0.061051425 | V23: =K23 -> 0 | W23: =V23/$E$4 -> 0 | X23: =P23+W23 -> 0.061051425 | Z23: =O23 -> 29000 | AA23: =Z23/$E$4 -> 0.061051425 | AC23: =R23 -> 0 | AD23: =AC23/$E$4 -> 0 | AE23: =AA23+AD23 -> 0.061051425 | AG23: =V23 -> 0 | AH23: =AG23/$E$4 -> 0 | AI23: =AA23+AH23 -> 0.061051425
A24: g | B24: Security Equipments | D24: ='HK - Secr Equipments'!H22 -> 43000 | E24: =D24/$E$4 -> 0.090524526 | H24: =G24/$E$4 -> 0 | I24: =E24+H24 -> 0.090524526 | L24: =K24/$E$4 -> 0 | M24: =E24+L24 -> 0.090524526 | O24: =D24 -> 43000 | P24: =O24/$E$4 -> 0.090524526 | R24: =G24 -> 0 | S24: =R24/$E$4 -> 0 | T24: =P24+S24 -> 0.090524526 | V24: =K24 -> 0 | W24: =V24/$E$4 -> 0 | X24: =P24+W24 -> 0.090524526 | Z24: =O24 -> 43000 | AA24: =Z24/$E$4 -> 0.090524526 | AC24: =R24 -> 0 | AD24: =AC24/$E$4 -> 0 | AE24: =AA24+AD24 -> 0.090524526 | AG24: =V24 -> 0 | AH24: =AG24/$E$4 -> 0 | AI24: =AA24+AH24 -> 0.090524526
A26: 3 | B26: AMC Charges | D26: ='AMC Cost'!D13 -> 0 | E26: =D26/$E$4 -> 0 | G26: ='AMC Cost'!D18 -> 0 | H26: =G26/$H$4 -> 0 | I26: =E26+H26 -> 0 | K26: ='AMC Cost'!D23 -> 0 | L26: =K26/$L$4 -> 0 | M26: =E26+L26 -> 0 | O26: ='AMC Cost'!E13 -> 128070 | P26: =O26/$E$4 -> 0.26961572 | R26: ='AMC Cost'!E23 -> 0 | S26: =R26/$H$4 -> 0 | T26: =P26+S26 -> 0.26961572 | V26: ='AMC Cost'!E18 -> 183333.33 | W26: =V26/$L$4 -> 0.6368261 | X26: =P26+W26 -> 0.90644183 | Z26: ='AMC Cost'!F13 -> 403829.34 | AA26: =Z26/$E$4 -> 0.85015023 | AC26: ='AMC Cost'!F23 -> 60833.333 | AD26: =AC26/$H$4 -> 0.32509747 | AE26: =AA26+AD26 -> 1.1752477 | AG26: ='AMC Cost'!F18 -> 191666.67 | AH26: =AG26/$L$4 -> 0.66577274 | AI26: =AA26+AH26 -> 1.515923
A28: 4 | B28: Electricity Cost ( Utility & Common Area HVAC) | D28: =SUM(D29:D30) -> 142946.15 | E28: =SUM(E29:E30) -> 0.30093331 | G28: =SUM(G29:G30) -> 654927.13 | H28: =SUM(H29:H30) -> 1.3787667 | I28: =SUM(I29:I30) -> 1.6797 | K28: =SUM(K29:K30) -> 455237.06 | L28: =SUM(L29:L30) -> 0.95837487 | M28: =SUM(M29:M30) -> 1.2593082 | O28: =SUM(O29:O30) -> 150093.45 | P28: =SUM(P29:P30) -> 0.31597997 | R28: =SUM(R29:R30) -> 687673.49 | S28: =SUM(S29:S30) -> 1.447705 | T28: =SUM(T29:T30) -> 1.763685 | V28: =SUM(V29:V30) -> 477998.92 | W28: =SUM(W29:W30) -> 1.0062936 | X28: =SUM(X29:X30) -> 1.3222736 | Z28: =SUM(Z29:Z30) -> 157598.13 | AA28: =SUM(AA29:AA30) -> 0.33177897 | AC28: =SUM(AC29:AC30) -> 722057.16 | AD28: =SUM(AD29:AD30) -> 1.5200903 | AE28: =SUM(AE29:AE30) -> 1.8518693 | AG28: =SUM(AG29:AG30) -> 501898.86 | AH28: =SUM(AH29:AH30) -> 1.0566083 | AI28: =SUM(AI29:AI30) -> 1.3883873
A29: a | B29: Common Area Electricity Expense | D29: ='Comm Electrical load'!D9 -> 142946.15 | E29: =D29/$E$4 -> 0.30093331 | G29: ='Comm Electrical load'!D19 -> 98607.656 | H29: =G29/$E$4 -> 0.20759096 | I29: =E29+H29 -> 0.50852427 | K29: ='Comm Electrical load'!D29 -> 40071.331 | L29: =K29/$E$4 -> 0.084359029 | M29: =E29+L29 -> 0.38529233 | O29: =D29*105% -> 150093.45 | P29: =O29/$E$4 -> 0.31597997 | R29: =G29*105% -> 103538.04 | S29: =R29/$E$4 -> 0.21797051 | T29: =P29+S29 -> 0.53395048 | V29: =K29*105% -> 42074.898 | W29: =V29/$E$4 -> 0.08857698 | X29: =P29+W29 -> 0.40455695 | Z29: =O29*105% -> 157598.13 | AA29: =Z29/$E$4 -> 0.33177897 | AC29: =R29*105% -> 108714.94 | AD29: =AC29/$E$4 -> 0.22886903 | AE29: =AA29+AD29 -> 0.560648 | AG29: =V29*105% -> 44178.642 | AH29: =AG29/$E$4 -> 0.093005829 | AI29: =AA29+AH29 -> 0.4247848
A30: b | B30: HVAC Expense for common area | E30: =D30/$E$4 -> 0 | G30: ='HVAC-Mall'!C26 -> 556319.48 | H30: =G30/$E$4 -> 1.1711757 | I30: =E30+H30 -> 1.1711757 | K30: ='Load Breakup'!I265 -> 415165.73 | L30: =K30/$E$4 -> 0.87401584 | M30: =E30+L30 -> 0.87401584 | O30: =D30*105% -> 0 | P30: =O30/$E$4 -> 0 | R30: =G30*105% -> 584135.45 | S30: =R30/$E$4 -> 1.2297345 | T30: =P30+S30 -> 1.2297345 | V30: =K30*105% -> 435924.02 | W30: =V30/$E$4 -> 0.91771663 | X30: =P30+W30 -> 0.91771663 | Z30: =O30*105% -> 0 | AA30: =Z30/$E$4 -> 0 | AC30: =R30*105% -> 613342.22 | AD30: =AC30/$E$4 -> 1.2912213 | AE30: =AA30+AD30 -> 1.2912213 | AG30: =V30*105% -> 457720.22 | AH30: =AG30/$E$4 -> 0.96360247 | AI30: =AA30+AH30 -> 0.96360247
A32: 5 | B32: Audits | D32: =SUM(D33:D38) -> 43333.333 | E32: =ROUND(SUM(E33:E38),2) -> 0.09 | G32: =SUM(G33:G38) -> 0 | H32: =ROUND(SUM(H33:H38),2) -> 0 | I32: =SUM(I33:I38) -> 0.091226267 | K32: =SUM(K33:K38) -> 0 | L32: =ROUND(SUM(L33:L38),2) -> 0 | M32: =SUM(M33:M38) -> 0.091226267 | O32: =SUM(O33:O38) -> 60833.333 | P32: =ROUND(SUM(P33:P38),2) -> 0.13 | R32: =SUM(R33:R38) -> 0 | S32: =ROUND(SUM(S33:S38),2) -> 0 | T32: =SUM(T33:T38) -> 0.12806764 | V32: =SUM(V33:V38) -> 0 | W32: =ROUND(SUM(W33:W38),2) -> 0 | X32: =SUM(X33:X38) -> 0.12806764 | Z32: =SUM(Z33:Z38) -> 60833.333 | AA32: =ROUND(SUM(AA33:AA38),2) -> 0.13 | AC32: =SUM(AC33:AC38) -> 0 | AD32: =ROUND(SUM(AD33:AD38),2) -> 0 | AE32: =SUM(AE33:AE38) -> 0.12806764 | AG32: =SUM(AG33:AG38) -> 0 | AH32: =ROUND(SUM(AH33:AH38),2) -> 0 | AI32: =SUM(AI33:AI38) -> 0.12806764
A33: a | B33: Energy Audit / Thermography and Harmonic Test | D33: 8333.3333 | E33: =D33/$E$4 -> 0.017543513 | H33: =G33/$E$4 -> 0 | I33: =E33+H33 -> 0.017543513 | L33: =K33/$E$4 -> 0 | M33: =E33+L33 -> 0.017543513 | O33: 8333.3333 | P33: =O33/$E$4 -> 0.017543513 | S33: =R33/$E$4 -> 0 | T33: =P33+S33 -> 0.017543513 | W33: =V33/$E$4 -> 0 | X33: =P33+W33 -> 0.017543513 | Z33: 8333.3333 | AA33: =Z33/$E$4 -> 0.017543513 | AD33: =AC33/$E$4 -> 0 | AE33: =AA33+AD33 -> 0.017543513 | AH33: =AG33/$E$4 -> 0 | AI33: =AA33+AH33 -> 0.017543513
A34: b | B34: Fire, Health & Safety Audits | D34: 8333.3333 | E34: =D34/$E$4 -> 0.017543513 | H34: =G34/$E$4 -> 0 | I34: =E34+H34 -> 0.017543513 | L34: =K34/$E$4 -> 0 | M34: =E34+L34 -> 0.017543513 | O34: 8333.3333 | P34: =O34/$E$4 -> 0.017543513 | S34: =R34/$E$4 -> 0 | T34: =P34+S34 -> 0.017543513 | W34: =V34/$E$4 -> 0 | X34: =P34+W34 -> 0.017543513 | Z34: 8333.3333 | AA34: =Z34/$E$4 -> 0.017543513 | AD34: =AC34/$E$4 -> 0 | AE34: =AA34+AD34 -> 0.017543513 | AH34: =AG34/$E$4 -> 0 | AI34: =AA34+AH34 -> 0.017543513
A35: c | B35: Indoor Air Quality and DG emmission testing | D35: 8333.3333 | E35: =D35/$E$4 -> 0.017543513 | H35: =G35/$E$4 -> 0 | I35: =E35+H35 -> 0.017543513 | L35: =K35/$E$4 -> 0 | M35: =E35+L35 -> 0.017543513 | O35: 8333.3333 | P35: =O35/$E$4 -> 0.017543513 | S35: =R35/$E$4 -> 0 | T35: =P35+S35 -> 0.017543513 | W35: =V35/$E$4 -> 0 | X35: =P35+W35 -> 0.017543513 | Z35: 8333.3333 | AA35: =Z35/$E$4 -> 0.017543513 | AD35: =AC35/$E$4 -> 0 | AE35: =AA35+AD35 -> 0.017543513 | AH35: =AG35/$E$4 -> 0 | AI35: =AA35+AH35 -> 0.017543513
A36: d | B36: Legal and professional servcies | D36: 8333.3333 | E36: =D36/$E$4 -> 0.017543513 | H36: =G36/$E$4 -> 0 | I36: =E36+H36 -> 0.017543513 | L36: =K36/$E$4 -> 0 | M36: =E36+L36 -> 0.017543513 | O36: 20833.333 | P36: =O36/$E$4 -> 0.043858782 | S36: =R36/$E$4 -> 0 | T36: =P36+S36 -> 0.043858782 | W36: =V36/$E$4 -> 0 | X36: =P36+W36 -> 0.043858782 | Z36: 20833.333 | AA36: =Z36/$E$4 -> 0.043858782 | AD36: =AC36/$E$4 -> 0 | AE36: =AA36+AD36 -> 0.043858782 | AH36: =AG36/$E$4 -> 0 | AI36: =AA36+AH36 -> 0.043858782
A37: e | B37: Statutory compliances (PF, ESIC, Ptax, Lab.Welfare, Licenses, Returns, Audit etc.) | D37: 5000 | E37: =D37/$E$4 -> 0.010526108 | H37: =G37/$E$4 -> 0 | I37: =E37+H37 -> 0.010526108 | L37: =K37/$E$4 -> 0 | M37: =E37+L37 -> 0.010526108 | O37: 10000 | P37: =O37/$E$4 -> 0.021052215 | S37: =R37/$E$4 -> 0 | T37: =P37+S37 -> 0.021052215 | W37: =V37/$E$4 -> 0 | X37: =P37+W37 -> 0.021052215 | Z37: 10000 | AA37: =Z37/$E$4 -> 0.021052215 | AD37: =AC37/$E$4 -> 0 | AE37: =AA37+AD37 -> 0.021052215 | AH37: =AG37/$E$4 -> 0 | AI37: =AA37+AH37 -> 0.021052215
A38: f | B38: Water Testing Charges | D38: 5000 | E38: =D38/$E$4 -> 0.010526108 | H38: =G38/$E$4 -> 0 | I38: =E38+H38 -> 0.010526108 | L38: =K38/$E$4 -> 0 | M38: =E38+L38 -> 0.010526108 | O38: 5000 | P38: =O38/$E$4 -> 0.010526108 | S38: =R38/$E$4 -> 0 | T38: =P38+S38 -> 0.010526108 | W38: =V38/$E$4 -> 0 | X38: =P38+W38 -> 0.010526108 | Z38: 5000 | AA38: =Z38/$E$4 -> 0.010526108 | AD38: =AC38/$E$4 -> 0 | AE38: =AA38+AD38 -> 0.010526108 | AH38: =AG38/$E$4 -> 0 | AI38: =AA38+AH38 -> 0.010526108
A40: 6 | B40: Liosaning & Licenses Cost | D40: =SUM(D41:D49) -> 37891.667 | E40: =SUM(E41:E49) -> 0.079770353 | G40: =SUM(G41:G49) -> 0 | H40: =SUM(H41:H49) -> 0 | I40: =SUM(I41:I49) -> 0.079770353 | K40: =SUM(K41:K49) -> 0 | L40: =SUM(L41:L49) -> 0 | M40: =SUM(M41:M49) -> 0.079770353 | O40: =SUM(O41:O49) -> 37391.667 | P40: =SUM(P41:P49) -> 0.078717742 | R40: =SUM(R41:R49) -> 0 | S40: =SUM(S41:S49) -> 0 | T40: =SUM(T41:T49) -> 0.078717742 | V40: =SUM(V41:V49) -> 0 | W40: =SUM(W41:W49) -> 0 | X40: =SUM(X41:X49) -> 0.078717742 | Z40: =SUM(Z41:Z49) -> 37391.667 | AA40: =SUM(AA41:AA49) -> 0.078717742 | AC40: =SUM(AC41:AC49) -> 0 | AD40: =SUM(AD41:AD49) -> 0 | AE40: =SUM(AE41:AE49) -> 0.078717742 | AG40: =SUM(AG41:AG49) -> 0 | AH40: =SUM(AH41:AH49) -> 0 | AI40: =SUM(AI41:AI49) -> 0.078717742
A41: a | B41: Electrical and DG License renewal | D41: 208.33333 | E41: =D41/$E$4 -> 0.00043858782 | H41: =G41/$E$4 -> 0 | I41: =E41+H41 -> 0.00043858782 | L41: =K41/$E$4 -> 0 | M41: =E41+L41 -> 0.00043858782 | O41: 208.33333 | P41: =O41/$E$4 -> 0.00043858782 | S41: =R41/$E$4 -> 0 | T41: =P41+S41 -> 0.00043858782 | W41: =V41/$E$4 -> 0 | X41: =P41+W41 -> 0.00043858782 | Z41: 208.33333 | AA41: =Z41/$E$4 -> 0.00043858782 | AD41: =AC41/$E$4 -> 0 | AE41: =AA41+AD41 -> 0.00043858782 | AH41: =AG41/$E$4 -> 0 | AI41: =AA41+AH41 -> 0.00043858782
A42: b | B42: Lift License Renewal | D42: 2500 | E42: =D42/$E$4 -> 0.0052630538 | H42: =G42/$E$4 -> 0 | I42: =E42+H42 -> 0.0052630538 | L42: =K42/$E$4 -> 0 | M42: =E42+L42 -> 0.0052630538 | O42: 2000 | P42: =O42/$E$4 -> 0.0042104431 | S42: =R42/$E$4 -> 0 | T42: =P42+S42 -> 0.0042104431 | W42: =V42/$E$4 -> 0 | X42: =P42+W42 -> 0.0042104431 | Z42: 2000 | AA42: =Z42/$E$4 -> 0.0042104431 | AD42: =AC42/$E$4 -> 0 | AE42: =AA42+AD42 -> 0.0042104431 | AH42: =AG42/$E$4 -> 0 | AI42: =AA42+AH42 -> 0.0042104431
A43: c | B43: Fire NOC | D43: 83.333333 | E43: =D43/$E$4 -> 0.00017543513 | H43: =G43/$E$4 -> 0 | I43: =E43+H43 -> 0.00017543513 | L43: =K43/$E$4 -> 0 | M43: =E43+L43 -> 0.00017543513 | O43: 83.333333 | P43: =O43/$E$4 -> 0.00017543513 | S43: =R43/$E$4 -> 0 | T43: =P43+S43 -> 0.00017543513 | W43: =V43/$E$4 -> 0 | X43: =P43+W43 -> 0.00017543513 | Z43: 83.333333 | AA43: =Z43/$E$4 -> 0.00017543513 | AD43: =AC43/$E$4 -> 0 | AE43: =AA43+AD43 -> 0.00017543513 | AH43: =AG43/$E$4 -> 0 | AI43: =AA43+AH43 -> 0.00017543513
A44: d | B44: Labour license and registration | D44: 4166.6667 | E44: =D44/$E$4 -> 0.0087717564 | H44: =G44/$E$4 -> 0 | I44: =E44+H44 -> 0.0087717564 | L44: =K44/$E$4 -> 0 | M44: =E44+L44 -> 0.0087717564 | O44: 4166.6667 | P44: =O44/$E$4 -> 0.0087717564 | S44: =R44/$E$4 -> 0 | T44: =P44+S44 -> 0.0087717564 | W44: =V44/$E$4 -> 0 | X44: =P44+W44 -> 0.0087717564 | Z44: 4166.6667 | AA44: =Z44/$E$4 -> 0.0087717564 | AD44: =AC44/$E$4 -> 0 | AE44: =AA44+AD44 -> 0.0087717564 | AH44: =AG44/$E$4 -> 0 | AI44: =AA44+AH44 -> 0.0087717564
A45: e | B45: Liosaning & Licenses Cost | D45: 25000 | E45: =D45/$E$4 -> 0.052630538 | H45: =G45/$E$4 -> 0 | I45: =E45+H45 -> 0.052630538 | L45: =K45/$E$4 -> 0 | M45: =E45+L45 -> 0.052630538 | O45: 25000 | P45: =O45/$E$4 -> 0.052630538 | S45: =R45/$E$4 -> 0 | T45: =P45+S45 -> 0.052630538 | W45: =V45/$E$4 -> 0 | X45: =P45+W45 -> 0.052630538 | Z45: 25000 | AA45: =Z45/$E$4 -> 0.052630538 | AD45: =AC45/$E$4 -> 0 | AE45: =AA45+AD45 -> 0.052630538 | AH45: =AG45/$E$4 -> 0 | AI45: =AA45+AH45 -> 0.052630538
A46: f | B46: Environmental and Pollution Control Inspections | D46: 4166.6667 | E46: =D46/$E$4 -> 0.0087717564 | H46: =G46/$E$4 -> 0 | I46: =E46+H46 -> 0.0087717564 | L46: =K46/$E$4 -> 0 | M46: =E46+L46 -> 0.0087717564 | O46: 4166.6667 | P46: =O46/$E$4 -> 0.0087717564 | S46: =R46/$E$4 -> 0 | T46: =P46+S46 -> 0.0087717564 | W46: =V46/$E$4 -> 0 | X46: =P46+W46 -> 0.0087717564 | Z46: 4166.6667 | AA46: =Z46/$E$4 -> 0.0087717564 | AD46: =AC46/$E$4 -> 0 | AE46: =AA46+AD46 -> 0.0087717564 | AH46: =AG46/$E$4 -> 0 | AI46: =AA46+AH46 -> 0.0087717564
...

Sheet AMC Cost
A1: ANNUAL MAINTENANCE CHARGE ESTIMATION- | I1: INDEX
A2: S.No. as per Budget | B2: Package No. | C2: Package Name | D2: DLP | E2: 2nd Year | F2: 3rd Year | G2: 4th Year | H2: 5th Year
A3: 1 | B3: TIIPL/MEP-003(PART-1) | C3: Fire Fighting | E3: =482405+76630 -> 559035 | F3: =E3*107% -> 598167.45 | G3: =F3*107% -> 640039.17 | H3: =G3*107% -> 684841.91
A4: 2 | B4: TIIPL/MEP-009 | C4: FAS | E4: 263130 | F4: =E4*107% -> 281549.1 | G4: =F4*107% -> 301257.54 | H4: =G4*107% -> 322345.56
C5: CCTV | E5: 166000 | F5: =E5*107% -> 177620 | G5: =F5*107% -> 190053.4 | H5: =G5*107% -> 203357.14
C6: IBMS&PAS | E6: 208675 | F6: =E6*107% -> 223282.25 | G6: =F6*107% -> 238912.01 | H6: =G6*107% -> 255635.85
A7: 4 | B7: TIIPL/MEP - 002 | C7: Electrical Panels ( HT / LT) | E7: =5*6000+(10*3500)*2 -> 100000 | F7: =E7*105% -> 105000 | G7: =F7*105% -> 110250 | H7: =G7*105% -> 115762.5
A8: 5 | B8: TIIPL/MEP - 11 Part 1 | C8: Fire Fighting Pumps | D8: 0
A9: 6 | B9: TIIPL/INT - 002 | C9: Elevators | D9: 0 | E9: 0 | F9: 3008333.3 | G9: =F9*107% -> 3218916.7 | H9: =G9*107% -> 3444240.8
A10: 7 | B10: TIIPL/MEP-005 | C10: Diesel Generators | D10: 0 | E10: 0 | F10: 200000 | G10: =+F10+F10*10% -> 220000 | H10: =+G10+G10*10% -> 242000
C11: IT Infrastructure- Computers | E11: =20*6000*2 -> 240000 | F11: =E11*105% -> 252000 | G11: =F11*105% -> 264600 | H11: =G11*105% -> 277830
C12: Annual Cost | D12: =SUM(D3:D11) -> 0 | E12: =SUM(E3:E11) -> 1536840 | F12: =SUM(F3:F11) -> 4845952.1 | G12: =SUM(G3:G11) -> 5184028.8 | H12: =SUM(H3:H11) -> 5546013.8
C13: Monthly Cost | D13: =D12/12 -> 0 | E13: =E12/12 -> 128070 | F13: =F12/12 -> 403829.34 | G13: =G12/12 -> 432002.4 | H13: =H12/12 -> 462167.82
C14: Per sq ft Cost | D14: =D12/12/'CAM Variables'!$J$3 -> 0 | E14: =E12/12/'CAM Variables'!$J$3 -> 0.26961572 | F14: =F12/12/'CAM Variables'!$J$3 -> 0.85015023 | G14: =G12/12/'CAM Variables'!$J$3 -> 0.90946075 | H14: =H12/12/'CAM Variables'!$J$3 -> 0.97296564
A16: Office
B17: TIIPL/MEP -7(PART-2) | C17: Package Units | E17: 2200000 | F17: 2300000 | G17: 2400000 | H17: 2600000
B18: Office Total | C18: Monthly Cost | D18: =D17/12 -> 0 | E18: =E17/12 -> 183333.33 | F18: =F17/12 -> 191666.67 | G18: =G17/12 -> 200000 | H18: =H17/12 -> 216666.67
A21: Mall
B22: TIIPL/MEP-007 | C22: Chillers | D22: 0 | E22: 0 | F22: 730000 | G22: 730000 | H22: 730000
B23: Mall Total | C23: Monthly Cost | D23: =D22/12 -> 0 | E23: =E22/12 -> 0 | F23: =F22/12 -> 60833.333 | G23: =G22/12 -> 60833.333 | H23: =H22/12 -> 60833.333

Sheet Comm Electrical load
A1: ELECTRICAL EXPENSE CALCULATION | E1: INDEX
A2: COMM. UTILITIES
A4: Common Area Electrcity Consumption
A5: Total Unit Consumed per month | B5: ='Load Breakup'!I190 -> 19752.469
A6: Source | B6: Rate per unit | C6: Units Comsumed | D6: Cost
A7: DG Set | B7: ='CAM Variables'!$E$9 -> 18.29 | C7: =B5*'CAM Variables'!$E$10 -> 1234.5293 | D7: =C7*B7 -> 22579.541
A8: UPPCL | B8: ='CAM Variables'!$G$8 -> 6.5 | C8: =B5*'CAM Variables'!$G$10 -> 18517.939 | D8: =C8*B8 -> 120366.61
A9: TOTAL UNIT CHARGES | D9: =SUM(D7:D8) -> 142946.15
A11: ELECTRICAL EXPENSE CALCULATION
A12: MALL ELECTRICITY EXPENSES
A14: Common Area Electrcity Consumption
A15: Total Unit Consumed per month | B15: ='Load Breakup'!I226 -> 13625.723
A16: Source | B16: Rate per unit | C16: Units Comsumed | D16: Cost
A17: DG Set | B17: ='CAM Variables'!$E$9 -> 18.29 | C17: =B15*'CAM Variables'!$E$10 -> 851.6077 | D17: =C17*B17 -> 15575.905
A18: UPPCL | B18: ='CAM Variables'!$G$8 -> 6.5 | C18: =B15*'CAM Variables'!$G$10 -> 12774.116 | D18: =C18*B18 -> 83031.751
A19: TOTAL UNIT CHARGES | D19: =SUM(D17:D18) -> 98607.656
A21: ELECTRICAL EXPENSE CALCULATION
A22: OFFICE ELECTRICITY EXPENSES
A24: Common Area Electrcity Consumption
A25: Total Unit Consumed per month | B25: ='Load Breakup'!I243 -> 5537.1042
A26: Source | B26: Rate per unit | C26: Units Comsumed | D26: Cost
A27: DG Set | B27: ='CAM Variables'!$E$9 -> 18.29 | C27: =B25*'CAM Variables'!$E$10 -> 346.06901 | D27: =C27*B27 -> 6329.6022
A28: UPPCL | B28: ='CAM Variables'!$G$8 -> 6.5 | C28: =B25*'CAM Variables'!$G$10 -> 5191.0352 | D28: =C28*B28 -> 33741.729
A29: TOTAL UNIT CHARGES | D29: =SUM(D27:D28) -> 40071.331

Sheet Load Breakup
A1: COMM. AREA ELECTRAL LOAD DETAIL - ELECTRICITY CONSUMPTION | L1: INDEX
A2: Sl.No | B2: DESCRIPTION OF AREA | C2: EQUIPMENT DETAILS | D2: CAPACITY IN KW | E2: Diversity Factor-Load | F2: Diversity Factor-Seasonal | G2: Daily hrs of operation | H2: Daily Units | I2: Monthly units | J2: Monthly Cost
A4: Comm. Utilities
A5: Lighting Load- Comm | D5: =SUM(D6:D17) -> 69.18 | H5: =SUM(H6:H17) -> 273.44856 | I5: =SUM(I6:I17) -> 8340.1811 | K5: =I5*'HVAC-Mall'!$C$14 -> 66502.519 | L5: =K5*12 -> 798030.23
A6: 1 | B6: STAIRCASE | C6: bulk head (11w) | D6: 1.6 | E6: 0.5 | F6: 0.5 | G6: 18 | H6: =D6*E6*F6*G6 -> 7.2 | I6: =H6*30.5 -> 219.6
A7: 2 | B7: LIFT SHAFT | C7: bulk head (9w) | D7: 1.78 | E7: 0.2 | F7: 0.5 | G7: 1 | H7: =D7*E7*F7*G7 -> 0.178 | I7: =H7*30.5 -> 5.429
A8: 3 | B8: External Lighting | D8: 10 | E8: 0.7 | F8: 0.5 | G8: 10 | H8: =D8*E8*F8*G8 -> 35 | I8: =H8*30.5 -> 1067.5
A9: 4 | B9: Basement-1 | C9: fluroscent lamp (2*28w) | D9: 14.84 | E9: 0.7 | F9: 0.5 | G9: 12 | H9: =D9*E9*F9*G9 -> 62.328 | I9: =H9*30.5 -> 1901.004
C10: fluroscent lamp (1*28w) | D10: 1.008 | E10: 0.7 | F10: 0.3 | G10: 18 | H10: =D10*E10*F10*G10 -> 3.81024 | I10: =H10*30.5 -> 116.21232
C11: fluroscent lamp (1*9w) | D11: 0.108 | E11: 0.7 | F11: 0.5 | G11: 18 | H11: =D11*E11*F11*G11 -> 0.6804 | I11: =H11*30.5 -> 20.7522
A12: 5 | B12: Basement-2 | C12: fluroscent lamp (2*28w) | D12: 8.288 | E12: 0.7 | F12: 0.5 | G12: 12 | H12: =D12*E12*F12*G12 -> 34.8096 | I12: =H12*30.5 -> 1061.6928
C13: fluroscent lamp (1*28w) | D13: 4.9 | E13: 0.7 | F13: 0.3 | G13: 18 | H13: =D13*E13*F13*G13 -> 18.522 | I13: =H13*30.5 -> 564.921
A14: 6 | B14: Basement-3 | C14: fluroscent lamp (2*28w) | D14: 12.152 | E14: 0.7 | F14: 0.5 | G14: 12 | H14: =D14*E14*F14*G14 -> 51.0384 | I14: =H14*30.5 -> 1556.6712
C15: fluroscent lamp (1*28w) | D15: 1.372 | E15: 0.7 | F15: 0.3 | G15: 18 | H15: =D15*E15*F15*G15 -> 5.18616 | I15: =H15*30.5 -> 158.17788
A16: 7 | B16: Basement-4 | C16: fluroscent lamp (2*28w) | D16: 12.04 | E16: 0.7 | F16: 0.5 | G16: 12 | H16: =D16*E16*F16*G16 -> 50.568 | I16: =H16*30.5 -> 1542.324
C17: fluroscent lamp (1*28w) | D17: 1.092 | E17: 0.7 | F17: 0.3 | G17: 18 | H17: =D17*E17*F17*G17 -> 4.12776 | I17: =H17*30.5 -> 125.89668
A19: Ventilation and Exhaust- Comm | D19: =SUM(D20:D125) -> 1057.8 | H19: =SUM(H20:H125) -> 112.3051 | I19: =SUM(I20:I125) -> 3425.3056 | K19: =6000000*70% -> 4200000
A20: 119 | B20: DG- EXAUST AIR | C20: AXIAL FAN | D20: 15 | E20: 0.5 | F20: 0.7 | G20: =0.1*12/12 -> 0.1 | H20: =D20*E20*F20*G20 -> 0.525 | I20: =H20*30.5 -> 16.0125
A21: 120 | B21: DG- EXAUST AIR | C21: AXIAL FAN | D21: 15 | E21: 0.5 | F21: 0.7 | G21: =0.1*12/12 -> 0.1 | H21: =D21*E21*F21*G21 -> 0.525 | I21: =H21*30.5 -> 16.0125
A22: 121 | B22: DG- EXAUST AIR | C22: AXIAL FAN | D22: 15 | E22: 0.5 | F22: 0.7 | G22: =0.1*12/12 -> 0.1 | H22: =D22*E22*F22*G22 -> 0.525 | I22: =H22*30.5 -> 16.0125
A23: 122 | B23: DG- EXAUST AIR | C23: AXIAL FAN | D23: 15 | E23: 0.5 | F23: 0.7 | G23: =0.1*12/12 -> 0.1 | H23: =D23*E23*F23*G23 -> 0.525 | I23: =H23*30.5 -> 16.0125
A24: 123 | B24: DG-FRESH AIR | C24: AXIAL FAN | D24: 15 | E24: 0.5 | F24: 0.7 | G24: =0.1*12/12 -> 0.1 | H24: =D24*E24*F24*G24 -> 0.525 | I24: =H24*30.5 -> 16.0125
A25: 124 | B25: DG-FRESH AIR | C25: AXIAL FAN | D25: 15 | E25: 0.5 | F25: 0.7 | G25: =0.1*12/12 -> 0.1 | H25: =D25*E25*F25*G25 -> 0.525 | I25: =H25*30.5 -> 16.0125
A26: 125 | B26: DG-FRESH AIR | C26: AXIAL FAN | D26: 15 | E26: 0.5 | F26: 0.7 | G26: =0.1*12/12 -> 0.1 | H26: =D26*E26*F26*G26 -> 0.525 | I26: =H26*30.5 -> 16.0125
A27: 126 | B27: DG-FRESH AIR | C27: AXIAL FAN | D27: 15 | E27: 0.5 | F27: 0.7 | G27: =0.1*12/12 -> 0.1 | H27: =D27*E27*F27*G27 -> 0.525 | I27: =H27*30.5 -> 16.0125
A28: 127 | B28: TRASFORMER ROOM EXAUST AIR | C28: AXIAL FAN | D28: 2.2 | E28: 0.5 | F28: 0.7 | G28: 11 | H28: =D28*E28*F28*G28 -> 8.47 | I28: =H28*30.5 -> 258.335
A29: 128 | B29: TRASFORMER ROOM EXAUST AIR | C29: AXIAL FAN | D29: 2.2 | E29: 0.5 | F29: 0.7 | G29: 11 | H29: =D29*E29*F29*G29 -> 8.47 | I29: =H29*30.5 -> 258.335
